# Example 5: Panic
# Demonstrates the panic mechanism for unrecoverable errors.

import std.io as io;
import std.error.Error as Error;
static let println = io.println;

func cause_panic() -> nil {
    println("About to cause an unrecoverable error...");
    raise Error("FatalError", msg="System integrity compromised.", panic=True);
    println("This line will never be reached.");
}

func main() -> int {
    # Uncomment the following line to see panic in action.
    # cause_panic();
    return 0;
}
